## 函数异常

函数中使用异常，使用raise关键字将异常抛出

```python
async def get_user(conn: AsyncIOMotorClient, username: str) -> User:
    row = await get_user_collection(conn).find_one({"username": username})
    if row:
        return User(**row)
    else:
		raise NoUserError
```

## 接口异常

接口中使用异常，使用try...except语法捕获异常。

```python
async def check_exist(username: str = Query(..., description="账户"), db: AsyncIOMotorClient = Depends(get_database)):
    try:
    	dbuser = await get_user(db, username)
    except NoUserError:
        return ResultInResponse(result="failed")
    return ResultInResponse()
try:
	...
except NoUserError:
	raise HTTPException(status_code=HTTP_400_BAD_REQUEST, detail=f"{e}")
```

